Workbook

Sheet Assumptions
B2: Assumptions:
B4: =" Alpino Protein Café" -> Alpino Protein Café
B6: Model Name | C6: Company-Owned Company-Operated (COCO)
B8: Café Format assumptions
B9: Café type | C9: Protein-focused QSR
B10: Sq. ft | C10: 800
B11: Seats | C11: 30
B12: Employee count | C12: 9
B14: Revenue assumptions
B15: Take-away% | C15: 40
B16: Subscription % | C16: =40*62% -> 24.8
B17: Online orders% (through Swiggy/Zomato) | C17: =C15-C16 -> 15.2
B18: Dine in % | C18: 60
B19: Weekdays / Month | C19: 22
B20: Weekends / Month | C20: 8
B21: AOV | C21: 300
B22: No of orders per day (weekdays) | C22: 80
B23: No of orders per day (weekends) | C23: 105
B24: Per month | C24: =C22*30 -> 2400
B25: Per year | C25: =C24*12 -> 28800
B26: COGS increment per year (as per food inflation trends) | C26: 0.07
B27: Salary increment per year to employees | C27: 0.005
B28: Salary increment per year to head chef | C28: 0.15
B29: Operational Costs escalation per year | C29: 0.05

Sheet P&L
B2: ="Income Statement of" & Assumptions!$B$4 -> Income Statement of Alpino Protein Café
B3: Years | C3: Workings | D3: 1 | E3: 2 | F3: =E3+1 -> 3 | G3: =F3+1 -> 4 | H3: =G3+1 -> 5 | I3: =H3+1 -> 6 | J3: =I3+1 -> 7 | K3: =J3+1 -> 8 | L3: =K3+1 -> 9 | M3: =L3+1 -> 10 | N3: =M3+1 -> 11
B4: Growth rate | D4: 0 | E4: 0 | F4: 0 | G4: 0.05 | H4: 0.1 | I4: 0.1 | J4: 0.1 | K4: 0.1 | L4: 0.1 | M4: 0.1 | N4: 0.1
B5: Revenue | C5: =A33 -> 1 | D5: =E36 -> 9360000 | E5: =D5*(1+E4) -> 9360000 | F5: =E5*(1+F4) -> 9360000 | G5: =F5*(1+G4) -> 9828000 | H5: =G5*(1+H4) -> 10810800 | I5: =H5*(1+I4) -> 11891880 | J5: =I5*(1+J4) -> 13081068 | K5: =J5*(1+K4) -> 14389175 | L5: =K5*(1+L4) -> 15828092 | ... N5: =M5*(1+N4) -> 19151992
E6: =D6
B7: Cost of Goods Sold | C7: =A45 -> 3 | D7: =D50 -> 3582000 | E7: =D7*(1+Assumptions!$C$26) -> 3832740 | F7: =E7*(1+Assumptions!$C$26) -> 4101031.8 | G7: =F7*(1+Assumptions!$C$26) -> 4388104 | H7: =G7*(1+Assumptions!$C$26) -> 4695271.3 | I7: =H7*(1+Assumptions!$C$26) -> 5023940.3 | J7: =I7*(1+Assumptions!$C$26) -> 5375616.1 | K7: =J7*(1+Assumptions!$C$26) -> 5751909.2 | L7: =K7*(1+Assumptions!$C$26) -> 6154542.9 | ... N7: =M7*(1+Assumptions!$C$26) -> 7046336.2
B8: COGS as % of sales | D8: =D7/D$5 -> 0.38269231 | E8: =E7/E$5 -> 0.40948077 | F8: =F7/F$5 -> 0.43814442 | G8: =G7/G$5 -> 0.44649003 | H8: =H7/H$5 -> 0.43431303 | I8: =I7/I$5 -> 0.42246813 | J8: =J7/J$5 -> 0.41094627 | K8: =K7/K$5 -> 0.39973865 | ... N8: =N7/N$5 -> 0.36791663
B10: Gross Profit | D10: =D5-D7 -> 5778000 | E10: =E5-E7 -> 5527260 | F10: =F5-F7 -> 5258968.2 | G10: =G5-G7 -> 5439896 | H10: =H5-H7 -> 6115528.7 | I10: =I5-I7 -> 6867939.7 | J10: =J5-J7 -> 7705451.9 | K10: =K5-K7 -> 8637265.6 | ... N10: =N5-N7 -> 12105656
B11: Gross Margin | D11: =D10/D5 -> 0.61730769 | E11: =E10/E5 -> 0.59051923 | F11: =F10/F5 -> 0.56185558 | G11: =G10/G5 -> 0.55350997 | H11: =H10/H5 -> 0.56568697 | I11: =I10/I5 -> 0.57753187 | J11: =J10/J5 -> 0.58905373 | K11: =K10/K5 -> 0.60026135 | ... N11: =N10/N5 -> 0.63208337
B13: Employee cost | C13: =A53 -> 4 | D13: =D56 -> 2100000 | E13: =E56 -> 2180100 | F13: =F56 -> 2271040.5 | G13: =G56 -> 2374441.7 | H13: =H56 -> 2492166.8 | I13: =I56 -> 2626358.5 | J13: =J56 -> 2779480.7 | K13: =K56 -> 2954367.2 | ... N13: =N56 -> 3644714.7
B14: Operating Costs | D14: =D66 -> 2550000 | E14: =D14*(1+Assumptions!$C$29) -> 2677500 | F14: =E14*(1+Assumptions!$C$29) -> 2811375 | G14: =F14*(1+Assumptions!$C$29) -> 2951943.8 | H14: =G14*(1+Assumptions!$C$29) -> 3099540.9 | I14: =H14*(1+Assumptions!$C$29) -> 3254518 | J14: =I14*(1+Assumptions!$C$29) -> 3417243.9 | K14: =J14*(1+Assumptions!$C$29) -> 3588106.1 | L14: =K14*(1+Assumptions!$C$29) -> 3767511.4 | ... N14: =M14*(1+Assumptions!$C$29) -> 4153681.3
B15: Capex (depreciated over 10 years) | C15: =A69 -> 7 | D15: =$C$79 -> 265000 | E15: =$C$79 -> 265000 | F15: =$C$79 -> 265000 | G15: =$C$79 -> 265000 | H15: =$C$79 -> 265000 | I15: =$C$79 -> 265000 | J15: =$C$79 -> 265000 | K15: =$C$79 -> 265000 | ... N15: =$C$79 -> 265000
B16: Operating Profit | D16: =D10-D13-D14-D15 -> 863000 | E16: =E10-E13-E14-E15 -> 404660 | F16: =F10-F13-F14-F15 -> -88447.3 | G16: =G10-G13-G14-G15 -> -151489.48 | H16: =H10-H13-H14-H15 -> 258820.94 | I16: =I10-I13-I14-I15 -> 722063.24 | J16: =J10-J13-J14-J15 -> 1243727.3 | K16: =K10-K13-K14-K15 -> 1829792.3 | ... N16: =N10-N13-N14-N15 -> 4042259.5
B17: Operating Profit Margin | D17: =D16/D5 -> 0.092200855 | E17: =E16/E5 -> 0.043232906 | F17: =F16/F5 -> -0.0094494979 | G17: =G16/G5 -> -0.01541407 | H17: =H16/H5 -> 0.023940961 | I17: =I16/I5 -> 0.060719015 | J17: =J16/J5 -> 0.095078419 | K17: =K16/K5 -> 0.12716451 | ... N17: =N16/N5 -> 0.21106209
B19: Non-Recurring Expenditure | C19: =A82 -> 8 | D19: =C85 -> 220000
B21: Profit before tax | D21: =D16-D19 -> 643000 | E21: =E16-E19 -> 404660 | F21: =F16-F19 -> -88447.3 | G21: =G16-G19 -> -151489.48 | H21: =H16-H19 -> 258820.94 | I21: =I16-I19 -> 722063.24 | J21: =J16-J19 -> 1243727.3 | K21: =K16-K19 -> 1829792.3 | ... N21: =N16-N19 -> 4042259.5
B22: Net Profit Margin | D22: =D21/D5 -> 0.068696581 | E22: =E21/E5 -> 0.043232906 | F22: =F21/F5 -> -0.0094494979 | G22: =G21/G5 -> -0.01541407 | H22: =H21/H5 -> 0.023940961 | I22: =I21/I5 -> 0.060719015 | J22: =J21/J5 -> 0.095078419 | K22: =K21/K5 -> 0.12716451 | ... N22: =N21/N5 -> 0.21106209
B24: Tax | D24: 0 | E24: 0 | F24: 0 | G24: 0 | H24: 0 | I24: 0 | J24: 0 | K24: 0 | L24: 0 | M24: 0 | N24: 0
B26: Profit after tax | D26: =D21-D24 -> 643000 | E26: =E21-E24 -> 404660 | F26: =F21-F24 -> -88447.3 | G26: =G21-G24 -> -151489.48 | H26: =H21-H24 -> 258820.94 | I26: =I21-I24 -> 722063.24 | J26: =J21-J24 -> 1243727.3 | K26: =K21-K24 -> 1829792.3 | ... N26: =N21-N24 -> 4042259.5
B27: Net Profit Margin | D27: =D26/D5 -> 0.068696581 | E27: =E26/E5 -> 0.043232906 | F27: =F26/F5 -> -0.0094494979 | G27: =G26/G5 -> -0.01541407 | H27: =H26/H5 -> 0.023940961 | I27: =I26/I5 -> 0.060719015 | J27: =J26/J5 -> 0.095078419 | K27: =K26/K5 -> 0.12716451 | ... N27: =N26/N5 -> 0.21106209
B32: Workings
A33: 1 | B33: Revenue | C33: No. of days in a year | D33: No. of orders | E33: Total sales
B34: weekdays | C34: =Assumptions!C19*12 -> 264 | D34: =C34*Assumptions!C22 -> 21120 | E34: =D34*Assumptions!C21 -> 6336000
B35: weekends | C35: =Assumptions!C20*12 -> 96 | D35: =Assumptions!C23*C35 -> 10080 | E35: =D35*Assumptions!C21 -> 3024000
C36: Total Sales | E36: =SUM(E34:E35) -> 9360000
A39: 2 | B39: Central Kitchen Costs | C39: Per month | D39: Per year
B40: Operating Costs | C40: 20000 | D40: =C40*12 -> 240000
B41: Employees | C41: =14000*5 -> 70000 | D41: =C41*12 -> 840000
C42: =SUM(C40:C41) -> 90000 | D42: =SUM(D40:D41) -> 1080000
A45: 3 | B45: COGS | C45: Per month | D45: Per year
B46: Raw material procurement costs | C46: 150000 | D46: =C46*12 -> 1800000
B47: Storage costs | C47: 40000 | D47: =C47*12 -> 480000
B48: Central Kitchen Costs | C48: =C42 -> 90000 | D48: =C48*12 -> 1080000
B49: Packaging | C49: 18500 | D49: =C49*12 -> 222000
D50: =SUM(D46:D49) -> 3582000
A53: 4 | B53: Employee cost | C53: Per month | D53: 1 | E53: 2 | F53: 3 | G53: 4 | H53: 5 | I53: 6 | J53: 7 | K53: 8 | L53: 9 | M53: 10 | N53: 11
B54: Salary to employees | C54: =15000*9 -> 135000 | D54: =C54*12 -> 1620000 | E54: =D54*(1+Assumptions!$C$27) -> 1628100 | F54: =E54*(1+Assumptions!$C$27) -> 1636240.5 | G54: =F54*(1+Assumptions!$C$27) -> 1644421.7 | H54: =G54*(1+Assumptions!$C$27) -> 1652643.8 | I54: =H54*(1+Assumptions!$C$27) -> 1660907 | J54: =I54*(1+Assumptions!$C$27) -> 1669211.6 | K54: =J54*(1+Assumptions!$C$27) -> 1677557.6 | L54: =K54*(1+Assumptions!$C$27) -> 1685945.4 | ... N54: =M54*(1+Assumptions!$C$27) -> 1702847
B55: Salary to Head Chef | C55: 40000 | D55: =C55*12 -> 480000 | E55: =D55*(1+Assumptions!$C$28) -> 552000 | F55: =E55*(1+Assumptions!$C$28) -> 634800 | G55: =F55*(1+Assumptions!$C$28) -> 730020 | H55: =G55*(1+Assumptions!$C$28) -> 839523 | I55: =H55*(1+Assumptions!$C$28) -> 965451.45 | J55: =I55*(1+Assumptions!$C$28) -> 1110269.2 | K55: =J55*(1+Assumptions!$C$28) -> 1276809.5 | L55: =K55*(1+Assumptions!$C$28) -> 1468331 | ... N55: =M55*(1+Assumptions!$C$28) -> 1941867.7
B56: Total salary costs | C56: =sum(C54:C55) -> 175000 | D56: =SUM(D54:D55) -> 2100000 | E56: =SUM(E54:E55) -> 2180100 | F56: =SUM(F54:F55) -> 2271040.5 | G56: =SUM(G54:G55) -> 2374441.7 | H56: =SUM(H54:H55) -> 2492166.8 | I56: =SUM(I54:I55) -> 2626358.5 | J56: =SUM(J54:J55) -> 2779480.7 | K56: =SUM(K54:K55) -> 2954367.2 | ... N56: =SUM(N54:N55) -> 3644714.7
A59: 6 | B59: Operational Costs | C59: (Assuming Sindhu Bhavan) | D59: Amount (₹)
...

Sheet Cashflows
B2: ="Free Cash Flows" & Assumptions!B4 -> Free Cash Flows Alpino Protein Café
B3: Years | C3: 0 | D3: 1 | E3: 2 | F3: 3 | G3: 4 | H3: 5 | I3: 6 | J3: 7 | K3: 8 | L3: 9 | M3: 10
B5: Operating Profit | D5: ='P&L'!D16 -> 863000 | E5: ='P&L'!E16 -> 404660 | F5: ='P&L'!F16 -> -88447.3 | G5: ='P&L'!G16 -> -151489.48 | H5: ='P&L'!H16 -> 258820.94 | I5: ='P&L'!I16 -> 722063.24 | J5: ='P&L'!J16 -> 1243727.3 | K5: ='P&L'!K16 -> 1829792.3 | ... M5: ='P&L'!M16 -> 3221697.9
B6: Add: Depreciation | D6: ='P&L'!D15 -> 265000 | E6: ='P&L'!E15 -> 265000 | F6: ='P&L'!F15 -> 265000 | G6: ='P&L'!G15 -> 265000 | H6: ='P&L'!H15 -> 265000 | I6: ='P&L'!I15 -> 265000 | J6: ='P&L'!J15 -> 265000 | K6: ='P&L'!K15 -> 265000 | ... M6: ='P&L'!M15 -> 265000
B7: Less- Non-recurring expenditure | C7: =-'P&L'!D19 -> -220000
B8: Less: Initial investment | C8: =-'P&L'!C77 -> -2650000
B9: Less: changes in working capital | C9: =-C26 -> -198493.15 | D9: =-D26 -> -10304.384 | E9: =-E26 -> -11025.69 | F9: =-F26 -> -14361.872 | G9: =-G26 -> -18008.518 | H9: =-H26 -> -19430.671 | I9: =-I26 -> -20968.53 | J9: =-J26 -> -22631.81 | ... M9: =-M26 -> -28484.409
B10: Free cashflows | C10: =SUM(C7:C9) -> -3068493.2 | D10: =SUM(D5:D9) -> 1117695.6 | E10: =SUM(E5:E9) -> 658634.31 | F10: =SUM(F5:F9) -> 162190.83 | G10: =SUM(G5:G9) -> 95502.003 | H10: =SUM(H5:H9) -> 504390.27 | I10: =SUM(I5:I9) -> 966094.71 | J10: =SUM(J5:J9) -> 1486095.5 | K10: =SUM(K5:K9) -> 2070361.2 | ... M10: =SUM(M5:M9) -> 3458213.5
B12: Cumulative CF | C12: =C10 -> -3068493.2 | D12: =D10+C12 -> -1950797.5 | E12: =E10+D12 -> -1292163.2 | F12: =F10+E12 -> -1129972.4 | G12: =G10+F12 -> -1034470.4 | H12: =H10+G12 -> -530080.12 | I12: =I10+H12 -> 436014.59 | J12: =J10+I12 -> 1922110 | K12: =K10+J12 -> 3992471.3 | ... M12: =M10+L12 -> 10176069
B13: Break even | C13: =5+(-1*H12)/((-1*H12)+I12) -> 5.5486834 | D13: years
B16: IRR | C16: =IRR(C10:M10) -> 0.26467241
B20: Working Capital Requirements
C21: 0 | D21: 1 | E21: 2 | F21: 3 | G21: 4 | H21: 5 | I21: 6 | J21: 7 | K21: 8 | L21: 9 | M21: 10 | N21: 11
B22: Inventory | D22: ='P&L'!D7*30/365 -> 294410.96 | E22: ='P&L'!E7*30/365 -> 315019.73 | F22: ='P&L'!F7*30/365 -> 337071.11 | G22: ='P&L'!G7*30/365 -> 360666.08 | H22: ='P&L'!H7*30/365 -> 385912.71 | I22: ='P&L'!I7*30/365 -> 412926.6 | J22: ='P&L'!J7*30/365 -> 441831.46 | K22: ='P&L'!K7*30/365 -> 472759.66 | ... N22: ='P&L'!N7*30/365 -> 579150.92
B23: Receivables | D23: ='P&L'!D5*2/365 -> 51287.671 | E23: ='P&L'!E5*2/365 -> 51287.671 | F23: ='P&L'!F5*2/365 -> 51287.671 | G23: ='P&L'!G5*2/365 -> 53852.055 | H23: ='P&L'!H5*2/365 -> 59237.26 | I23: ='P&L'!I5*2/365 -> 65160.986 | J23: ='P&L'!J5*2/365 -> 71677.085 | K23: ='P&L'!K5*2/365 -> 78844.793 | ... N23: ='P&L'!N5*2/365 -> 104942.42
B24: Payables | D24: ='P&L'!D7*15/365 -> 147205.48 | E24: ='P&L'!E7*15/365 -> 157509.86 | F24: ='P&L'!F7*15/365 -> 168535.55 | G24: ='P&L'!G7*15/365 -> 180333.04 | H24: ='P&L'!H7*15/365 -> 192956.36 | I24: ='P&L'!I7*15/365 -> 206463.3 | J24: ='P&L'!J7*15/365 -> 220915.73 | K24: ='P&L'!K7*15/365 -> 236379.83 | ... N24: ='P&L'!N7*15/365 -> 289575.46
B25: WC requirement | D25: =D22+D23-D24 -> 198493.15 | E25: =E22+E23-E24 -> 208797.53 | F25: =F22+F23-F24 -> 219823.22 | G25: =G22+G23-G24 -> 234185.1 | H25: =H22+H23-H24 -> 252193.62 | I25: =I22+I23-I24 -> 271624.29 | J25: =J22+J23-J24 -> 292592.82 | K25: =K22+K23-K24 -> 315224.63 | ... N25: =N22+N23-N24 -> 394517.88
B26: Working capital injection | C26: =D25-C25 -> 198493.15 | D26: =E25-D25 -> 10304.384 | E26: =F25-E25 -> 11025.69 | F26: =G25-F25 -> 14361.872 | G26: =H25-G25 -> 18008.518 | H26: =I25-H25 -> 19430.671 | I26: =J25-I25 -> 20968.53 | J26: =K25-J25 -> 22631.81 | ... M26: =N25-M25 -> 28484.409 | N26: -

Sheet Data Table 
B2: No of orders per year | C2: Average Order Value
C3: 0.2647 | D3: 250 | E3: 300 | F3: 350 | G3: 400 | H3: 500
C4: 27000 | D4: #NUM! | E4: -0.2026 | F4: 0.2938 | G4: 0.7365 | H4: 1.6333
C5: 29000 | D5: #NUM! | E5: 0.0451 | F5: 0.5216 | G5: 1.0032 | H5: 1.961
C6: 31000 | D6: #NUM! | E6: 0.2452 | F6: 0.7531 | G6: 1.2696 | H6: 2.2862
C7: 33000 | D7: -0.1301 | E7: 0.4398 | F7: 0.9865 | G7: 1.5344 | H7: 2.6091
C8: 35000 | D8: 0.0626 | E8: 0.637 | F8: 1.2197 | G8: 1.7975 | H8: 2.93
